Workbook

Sheet Raw Flow Data
A1: Date | B1: AL012 | C1: AL013 | D1: AL014 | E1: AL023 | F1: AL028 | G1: AL029 | H1: AL035 | I1: AL036 | J1: AL038 | K1: AL063 | L1: AM005 | M1: AM014 | N1: AM015 | O1: AM022 | P1: AM024 | Q1: AM026
A2: 46357 | B2: 3.168205 | C2: 2.20425 | D2: 2.665153 | E2: 3.43625 | F2: 3.225157 | G2: 2.57455 | H2: 3.67 | I2: 2.038 | J2: 3.130835 | K2: 4.02125 | L2: 22.68599 | M2: 19.81207 | N2: -999 | O2: 16.92209 | P2: 16.58575 | Q2: 18.88019
A3: 46357.01 | B3: 3.190769 | C3: 2.22525 | D3: 2.681334 | E3: 3.41125 | F3: 3.236456 | G3: 2.583137 | H3: 3.68375 | I3: 2.049 | J3: 3.145557 | K3: 4.04875 | L3: 22.45106 | M3: 19.72593 | N3: -999 | O3: 17.1022 | P3: 18.43384 | Q3: 15.47377
A4: 46357.021 | B4: 3.21641 | C4: 2.24625 | D4: 2.674793 | E4: 3.3875 | F4: 3.262896 | G4: 2.597148 | H4: 3.7075 | I4: 2.06 | J4: 3.148535 | K4: 4.07375 | L4: 22.20831 | M4: 19.66328 | N4: -999 | O4: 16.90642 | P4: 18.70008 | Q4: 16.69538
A5: 46357.031 | B5: 3.242051 | C5: 2.26575 | D5: 2.707717 | E5: 3.3925 | F5: 3.289562 | G5: 2.612967 | H5: 3.73125 | I5: 2.072 | J5: 3.148144 | K5: 4.12375 | L5: 21.40173 | M5: 19.91387 | N5: -999 | O5: 16.70282 | P5: 18.12843 | Q5: 13.89194
A6: 46357.042 | B6: 3.265641 | C6: 2.28675 | D6: 2.73515 | E6: 3.43375 | F6: 3.29363 | G6: 2.629012 | H6: 3.7575 | I6: 2.084 | J6: 3.140112 | K6: 4.15 | L6: 21.87158 | M6: 19.90604 | N6: -999 | O6: 16.92992 | P6: 18.02663 | Q6: 13.51606
A7: 46357.052 | B7: 3.289231 | C7: 2.3085 | D7: 2.76107 | E7: 3.4725 | F7: 3.295212 | G7: 2.642345 | H7: 3.78375 | I7: 2.096 | J7: 3.131763 | K7: 4.20125 | L7: 21.9264 | M7: 19.55365 | N7: -999 | O7: 17.04738 | P7: 19.00549 | Q7: 14.4401
A8: 46357.062 | B8: 3.31282 | C8: 2.331 | D8: 2.780839 | E8: 3.52 | F8: 3.299054 | G8: 2.654774 | H8: 3.81125 | I8: 2.109 | J8: 3.122534 | K8: 4.22875 | L8: 21.77761 | M8: 19.82773 | N8: -999 | O8: 16.8751 | P8: 18.58262 | Q8: 13.68834
A9: 46357.073 | B9: 3.33641 | C9: 2.3535 | D9: 2.799314 | E9: 3.5475 | F9: 3.304251 | G9: 2.667655 | H9: 3.83625 | I9: 2.122 | J9: 3.124414 | K9: 4.27875 | L9: 22.25529 | M9: 20.39155 | N9: -999 | O9: 16.96907 | P9: 18.61395 | Q9: 13.22632
A10: 46357.083 | B10: 3.361026 | C10: 2.376 | D10: 2.818888 | E10: 3.56875 | F10: 3.311031 | G10: 2.679632 | H10: 3.86375 | I10: 2.134 | J10: 3.126025 | K10: 4.305 | L10: 21.56618 | M10: 19.71027 | N10: -999 | O10: 17.07087 | P10: 18.55913 | Q10: 15.30149
A11: 46357.094 | B11: 3.386667 | C11: 2.39925 | D11: 2.838779 | E11: 3.5625 | F11: 3.319166 | G11: 2.690253 | H11: 3.89125 | I11: 2.132 | J11: 3.146167 | K11: 4.35625 | L11: 22.04386 | M11: 20.29758 | N11: -999 | O11: 17.27448 | P11: 18.80189 | Q11: 13.704
A12: 46357.104 | B12: 3.408205 | C12: 2.42175 | D12: 2.859207 | E12: 3.5325 | F12: 3.327754 | G12: 2.700649 | H12: 3.92 | I12: 2.126 | J12: 3.177197 | K12: 4.3825 | L12: 21.87158 | M12: 20.21144 | N12: -999 | O12: 17.17267 | P12: 18.28505 | Q12: 14.43227
A13: 46357.115 | B13: 3.43282 | C13: 2.4435 | D13: 2.879171 | E13: 3.48625 | F13: 3.337245 | G13: 2.711044 | H13: 3.94625 | I13: 2.122 | J13: 3.214893 | K13: 4.43375 | L13: 21.9029 | M13: 19.25608 | N13: -999 | O13: 16.8751 | P13: 17.63509 | Q13: 15.83399
... A29: 46357.281 | B29: 3.746667 | C29: 2.73225 | D29: 2.938479 | E29: 3.48875 | F29: 3.288884 | G29: 2.830589 | H29: 4.38625 | I29: 2.062 | J29: 3.384717 | K29: 4.35125 | L29: 21.62099 | M29: 18.58262 | N29: -999 | O29: 16.37393 | P29: 18.44167 | Q29: 20.41504
A31: INSTRUCTIONS: Delete the sample rows above (keep Row 1 headers), then paste your data from Row 2. Date in Column A; flow/pressure names as column headers. -999 = no-data.

Sheet Raw Pressure Data
A1: Date | B1: AL012 | C1: AL013 | D1: AL014 | E1: AL023 | F1: AL028 | G1: AL029 | H1: AL035 | I1: AL036 | J1: AL038 | K1: AL063 | L1: AM005 | M1: AM014 | N1: AM015 | O1: AM022 | P1: AM024 | Q1: AM026
A2: 46357 | B2: 3.373159 | C2: 2.438122 | D2: 2.885198 | E2: 3.633162 | F2: 3.428402 | G2: 2.797313 | H2: 3.8599 | I2: 2.27686 | J2: 3.33691 | K2: 4.200613 | L2: 22.30541 | M2: 19.517708 | N2: -999 | O2: 16.714427 | P2: 16.388178 | Q2: 18.613784
A3: 46357.01 | B3: 3.395046 | C3: 2.458492 | D3: 2.900894 | E3: 3.608912 | F3: 3.439362 | G3: 2.805643 | H3: 3.873237 | I3: 2.28753 | J3: 3.35119 | K3: 4.227288 | L3: 22.077528 | M3: 19.434152 | N3: -999 | O3: 16.889134 | P3: 18.180825 | Q3: 15.309557
A4: 46357.021 | B4: 3.419918 | C4: 2.478862 | D4: 2.894549 | E4: 3.585875 | F4: 3.465009 | G4: 2.819234 | H4: 3.896275 | I4: 2.2982 | J4: 3.354079 | K4: 4.251538 | L4: 21.842061 | M4: 19.373382 | N4: -999 | O4: 16.699227 | P4: 18.439078 | Q4: 16.494519
A5: 46357.031 | B5: 3.444789 | C5: 2.497777 | D5: 2.926485 | E5: 3.590725 | F5: 3.490875 | G5: 2.834578 | H5: 3.919312 | I5: 2.30984 | J5: 3.3537 | K5: 4.300038 | L5: 21.059678 | M5: 19.616454 | N5: -999 | O5: 16.501735 | P5: 17.884577 | Q5: 13.775182
A6: 46357.042 | B6: 3.467672 | C6: 2.518147 | D6: 2.953095 | E6: 3.630737 | F6: 3.494821 | G6: 2.850142 | H6: 3.944775 | I6: 2.32148 | J6: 3.345909 | K6: 4.3255 | L6: 21.515433 | M6: 19.608859 | N6: -999 | O6: 16.722022 | P6: 17.785831 | Q6: 13.410578
A7: 46357.052 | B7: 3.490554 | C7: 2.539245 | D7: 2.978238 | E7: 3.668325 | F7: 3.496356 | G7: 2.863075 | H7: 3.970237 | I7: 2.33312 | J7: 3.33781 | K7: 4.375212 | L7: 21.568608 | M7: 19.267041 | N7: -999 | O7: 16.835959 | P7: 18.735325 | Q7: 14.306897
A8: 46357.062 | B8: 3.513435 | C8: 2.56107 | D8: 2.997414 | E8: 3.7144 | F8: 3.500082 | G8: 2.875131 | H8: 3.996912 | I8: 2.34573 | J8: 3.328858 | K8: 4.401887 | L8: 21.424282 | M8: 19.532898 | N8: -999 | O8: 16.668847 | P8: 18.325141 | Q8: 13.57769
A9: 46357.073 | B9: 3.536318 | C9: 2.582895 | D9: 3.015335 | E9: 3.741075 | F9: 3.505123 | G9: 2.887625 | H9: 4.021162 | I9: 2.35834 | J9: 3.330682 | K9: 4.450387 | L9: 21.887631 | M9: 20.079804 | N9: -999 | O9: 16.759998 | P9: 18.355531 | Q9: 13.12953
A10: 46357.083 | B10: 3.560195 | C10: 2.60472 | D10: 3.034321 | E10: 3.761687 | F10: 3.5117 | G10: 2.899243 | H10: 4.047837 | I10: 2.36998 | J10: 3.332244 | K10: 4.47585 | L10: 21.219195 | M10: 19.418962 | N10: -999 | O10: 16.858744 | P10: 18.302356 | Q10: 15.142445
A11: 46357.094 | B11: 3.585067 | C11: 2.627272 | D11: 3.053616 | E11: 3.755625 | F11: 3.519591 | G11: 2.909545 | H11: 4.074512 | I11: 2.36804 | J11: 3.351782 | K11: 4.525562 | L11: 21.682544 | M11: 19.988653 | N11: -999 | O11: 17.056246 | P11: 18.537833 | Q11: 13.59288
A12: 46357.104 | B12: 3.605959 | C12: 2.649097 | D12: 3.073431 | E12: 3.726525 | F12: 3.527921 | G12: 2.91963 | H12: 4.1024 | I12: 2.36222 | J12: 3.381881 | K12: 4.551025 | L12: 21.515433 | M12: 19.905097 | N12: -999 | O12: 16.95749 | P12: 18.036498 | Q12: 14.299302
A13: 46357.115 | B13: 3.629835 | C13: 2.670195 | D13: 3.092796 | E13: 3.681662 | F13: 3.537128 | G13: 2.929713 | H13: 4.127862 | I13: 2.35834 | J13: 3.418446 | K13: 4.600737 | L13: 21.545813 | M13: 18.978398 | N13: -999 | O13: 16.668847 | P13: 17.406037 | Q13: 15.65897
... A29: 46357.281 | B29: 3.934267 | C29: 2.950282 | D29: 3.150325 | E29: 3.684087 | F29: 3.490217 | G29: 3.045671 | H29: 4.554663 | I29: 2.30014 | J29: 3.583175 | K29: 4.520713 | L29: 21.27236 | M29: 18.325141 | N29: -999 | O29: 16.182712 | P29: 18.18842 | Q29: 20.102589
A31: INSTRUCTIONS: Delete the sample rows above (keep Row 1 headers), then paste your data from Row 2. Date in Column A; flow/pressure names as column headers. -999 = no-data.

Sheet Dashboard
A1: Flow & Pressure Analysis Dashboard
A2: Flow (blank = hide) | B2: Name ▼ | C2: Scale | D2: Pressure (blank = hide) | E2: Name ▼ | F2: Offset
A3: Flow 1 ▼ | B3: AL012 | C3: 1 | D3: Pres 1 ▼ | E3: AL012 | F3: 0
A4: Flow 2 ▼ | B4: AL013 | C4: 1 | D4: Pres 2 ▼ | E4: AL013 | F4: 0
A5: Flow 3 ▼ | B5: AL014 | C5: 1 | D5: Pres 3 ▼ | E5: AL014 | F5: 0
A6: Flow 4 ▼ | B6: AL023 | C6: 1 | D6: Pres 4 ▼ | E6: AL023 | F6: 0
A7: Flow 5 ▼ | B7: AL028 | C7: 1 | D7: Pres 5 ▼ | E7: AL028 | F7: 0
A8: Flow 6 ▼ | B8: AL029 | C8: 1 | D8: Pres 6 ▼ | E8: AL029 | F8: 0
A9: Flow 7 ▼ | B9: AL035 | C9: 1 | D9: Pres 7 ▼ | E9: AL035 | F9: 0
A10: Flow 8 ▼ | B10: AL036 | C10: 1 | D10: Pres 8 ▼ | E10: AL036 | F10: 0
A11: Flow 9 ▼ | B11: AL038 | C11: 1 | D11: Pres 9 ▼ | E11: AL038 | F11: 0
A12: Flow 10 ▼ | B12: AL063 | C12: 1 | D12: Pres 10 ▼ | E12: AL063 | F12: 0
D13: Pres 11 ▼ | E13: AM005 | F13: 0
D14: Pres 12 ▼ | E14: AM014 | F14: 0
D15: Pres 13 ▼ | E15: AM015 | F15: 0
D16: Pres 14 ▼ | E16: AM022 | F16: 0
D17: Pres 15 ▼ | E17: AM024 | F17: 0
D18: Pres 16 ▼ | E18: AM026 | F18: 0
D19: Pres 17 ▼ | F19: 0
D20: Pres 18 ▼ | F20: 0
D21: Pres 19 ▼ | F21: 0
D22: Pres 20 ▼ | F22: 0
A23: ℹ Up to 10 flow and 20 pressure series. Leave a Name cell blank to hide that series. Each row has its own Scale (flow multiplier) and Offset (pressure addend). After pasting your own data, right-click a Name cell → Data Validation → update the Source range to match your column headers. Values of -999 are treated as no-data and excluded.
A24: FORMULA TABLE — updates automatically when you change selections or adjustments above
A25: Date | B25: Flow 1 Adj. | C25: Flow 2 Adj. | D25: Flow 3 Adj. | E25: Flow 4 Adj. | F25: Flow 5 Adj. | G25: Flow 6 Adj. | H25: Flow 7 Adj. | I25: Flow 8 Adj. | J25: Flow 9 Adj. | K25: Flow 10 Adj. | L25: Pres 1 Adj. | M25: Pres 2 Adj. | N25: Pres 3 Adj. | O25: Pres 4 Adj. | P25: Pres 5 Adj. | Q25: Pres 6 Adj. | R25: Pres 7 Adj. | S25: Pres 8 Adj. | T25: Pres 9 Adj. | U25: Pres 10 Adj. | V25: Pres 11 Adj. | W25: Pres 12 Adj. | X25: Pres 13 Adj. | Y25: Pres 14 Adj. | Z25: Pres 15 Adj. | AA25: Pres 16 Adj. | AB25: Pres 17 Adj. | AC25: Pres 18 Adj. | AD25: Pres 19 Adj. | AE25: Pres 20 Adj.
A26: =IFERROR(IF(INDEX('Raw Flow Data'!$A:$A,ROW()-24)="","",INDEX('Raw Flow Data'!$A:$A,ROW()-24)),"") | B26: =IFERROR(IF($B$3="","",IF(INDEX('Raw Flow Data'!$A:$ZZ,ROW()-24,MATCH($B$3,'Raw Flow Data'!$1:$1,0))=-999,"",INDEX('Raw Flow Data'!$A:$ZZ,ROW()-24,MATCH($B$3,'Raw Flow Data'!$1:$1,0))*$C$3)),"") | C26: =IFERROR(IF($B$4="","",IF(INDEX('Raw Flow Data'!$A:$ZZ,ROW()-24,MATCH($B$4,'Raw Flow Data'!$1:$1,0))=-999,"",INDEX('Raw Flow Data'!$A:$ZZ,ROW()-24,MATCH($B$4,'Raw Flow Data'!$1:$1,0))*$C$4)),"") | D26: =IFERROR(IF($B$5="","",IF(INDEX('Raw Flow Data'!$A:$ZZ,ROW()-24,MATCH($B$5,'Raw Flow Data'!$1:$1,0))=-999,"",INDEX('Raw Flow Data'!$A:$ZZ,ROW()-24,MATCH($B$5,'Raw Flow Data'!$1:$1,0))*$C$5)),"") | E26: =IFERROR(IF($B$6="","",IF(INDEX('Raw Flow Data'!$A:$ZZ,ROW()-24,MATCH($B$6,'Raw Flow Data'!$1:$1,0))=-999,"",INDEX('Raw Flow Data'!$A:$ZZ,ROW()-24,MATCH($B$6,'Raw Flow Data'!$1:$1,0))*$C$6)),"") | F26: =IFERROR(IF($B$7="","",IF(INDEX('Raw Flow Data'!$A:$ZZ,ROW()-24,MATCH($B$7,'Raw Flow Data'!$1:$1,0))=-999,"",INDEX('Raw Flow Data'!$A:$ZZ,ROW()-24,MATCH($B$7,'Raw Flow Data'!$1:$1,0))*$C$7)),"") | G26: =IFERROR(IF($B$8="","",IF(INDEX('Raw Flow Data'!$A:$ZZ,ROW()-24,MATCH($B$8,'Raw Flow Data'!$1:$1,0))=-999,"",INDEX('Raw Flow Data'!$A:$ZZ,ROW()-24,MATCH($B$8,'Raw Flow Data'!$1:$1,0))*$C$8)),"") | H26: =IFERROR(IF($B$9="","",IF(INDEX('Raw Flow Data'!$A:$ZZ,ROW()-24,MATCH($B$9,'Raw Flow Data'!$1:$1,0))=-999,"",INDEX('Raw Flow Data'!$A:$ZZ,ROW()-24,MATCH($B$9,'Raw Flow Data'!$1:$1,0))*$C$9)),"") | I26: =IFERROR(IF($B$10="","",IF(INDEX('Raw Flow Data'!$A:$ZZ,ROW()-24,MATCH($B$10,'Raw Flow Data'!$1:$1,0))=-999,"",INDEX('Raw Flow Data'!$A:$ZZ,ROW()-24,MATCH($B$10,'Raw Flow Data'!$1:$1,0))*$C$10)),"") | J26: =IFERROR(IF($B$11="","",IF(INDEX('Raw Flow Data'!$A:$ZZ,ROW()-24,MATCH($B$11,'Raw Flow Data'!$1:$1,0))=-999,"",INDEX('Raw Flow Data'!$A:$ZZ,ROW()-24,MATCH($B$11,'Raw Flow Data'!$1:$1,0))*$C$11)),"") | K26: =IFERROR(IF($B$12="","",IF(INDEX('Raw Flow Data'!$A:$ZZ,ROW()-24,MATCH($B$12,'Raw Flow Data'!$1:$1,0))=-999,"",INDEX('Raw Flow Data'!$A:$ZZ,ROW()-24,MATCH($B$12,'Raw Flow Data'!$1:$1,0))*$C$12)),"") | L26: =IFERROR(IF($E$3="","",IF(INDEX('Raw Pressure Data'!$A:$ZZ,ROW()-24,MATCH($E$3,'Raw Pressure Data'!$1:$1,0))=-999,"",INDEX('Raw Pressure Data'!$A:$ZZ,ROW()-24,MATCH($E$3,'Raw Pressure Data'!$1:$1,0))+$F$3)),"") | M26: =IFERROR(IF($E$4="","",IF(INDEX('Raw Pressure Data'!$A:$ZZ,ROW()-24,MATCH($E$4,'Raw Pressure Data'!$1:$1,0))=-999,"",INDEX('Raw Pressure Data'!$A:$ZZ,ROW()-24,MATCH($E$4,'Raw Pressure Data'!$1:$1,0))+$F$4)),"") | N26: =IFERROR(IF($E$5="","",IF(INDEX('Raw Pressure Data'!$A:$ZZ,ROW()-24,MATCH($E$5,'Raw Pressure Data'!$1:$1,0))=-999,"",INDEX('Raw Pressure Data'!$A:$ZZ,ROW()-24,MATCH($E$5,'Raw Pressure Data'!$1:$1,0))+$F$5)),"") | O26: =IFERROR(IF($E$6="","",IF(INDEX('Raw Pressure Data'!$A:$ZZ,ROW()-24,MATCH($E$6,'Raw Pressure Data'!$1:$1,0))=-999,"",INDEX('Raw Pressure Data'!$A:$ZZ,ROW()-24,MATCH($E$6,'Raw Pressure Data'!$1:$1,0))+$F$6)),"") | P26: =IFERROR(IF($E$7="","",IF(INDEX('Raw Pressure Data'!$A:$ZZ,ROW()-24,MATCH($E$7,'Raw Pressure Data'!$1:$1,0))=-999,"",INDEX('Raw Pressure Data'!$A:$ZZ,ROW()-24,MATCH($E$7,'Raw Pressure Data'!$1:$1,0))+$F$7)),"") | Q26: =IFERROR(IF($E$8="","",IF(INDEX('Raw Pressure Data'!$A:$ZZ,ROW()-24,MATCH($E$8,'Raw Pressure Data'!$1:$1,0))=-999,"",INDEX('Raw Pressure Data'!$A:$ZZ,ROW()-24,MATCH($E$8,'Raw Pressure Data'!$1:$1,0))+$F$8)),"") | R26: =IFERROR(IF($E$9="","",IF(INDEX('Raw Pressure Data'!$A:$ZZ,ROW()-24,MATCH($E$9,'Raw Pressure Data'!$1:$1,0))=-999,"",INDEX('Raw Pressure Data'!$A:$ZZ,ROW()-24,MATCH($E$9,'Raw Pressure Data'!$1:$1,0))+$F$9)),"") | S26: =IFERROR(IF($E$10="","",IF(INDEX('Raw Pressure Data'!$A:$ZZ,ROW()-24,MATCH($E$10,'Raw Pressure Data'!$1:$1,0))=-999,"",INDEX('Raw Pressure Data'!$A:$ZZ,ROW()-24,MATCH($E$10,'Raw Pressure Data'!$1:$1,0))+$F$10)),"") | T26: =IFERROR(IF($E$11="","",IF(INDEX('Raw Pressure Data'!$A:$ZZ,ROW()-24,MATCH($E$11,'Raw Pressure Data'!$1:$1,0))=-999,"",INDEX('Raw Pressure Data'!$A:$ZZ,ROW()-24,MATCH($E$11,'Raw Pressure Data'!$1:$1,0))+$F$11)),"") | U26: =IFERROR(IF($E$12="","",IF(INDEX('Raw Pressure Data'!$A:$ZZ,ROW()-24,MATCH($E$12,'Raw Pressure Data'!$1:$1,0))=-999,"",INDEX('Raw Pressure Data'!$A:$ZZ,ROW()-24,MATCH($E$12,'Raw Pressure Data'!$1:$1,0))+$F$12)),"") | V26: =IFERROR(IF($E$13="","",IF(INDEX('Raw Pressure Data'!$A:$ZZ,ROW()-24,MATCH($E$13,'Raw Pressure Data'!$1:$1,0))=-999,"",INDEX('Raw Pressure Data'!$A:$ZZ,ROW()-24,MATCH($E$13,'Raw Pressure Data'!$1:$1,0))+$F$13)),"") | W26: =IFERROR(IF($E$14="","",IF(INDEX('Raw Pressure Data'!$A:$ZZ,ROW()-24,MATCH($E$14,'Raw Pressure Data'!$1:$1,0))=-999,"",INDEX('Raw Pressure Data'!$A:$ZZ,ROW()-24,MATCH($E$14,'Raw Pressure Data'!$1:$1,0))+$F$14)),"") | X26: =IFERROR(IF($E$15="","",IF(INDEX('Raw Pressure Data'!$A:$ZZ,ROW()-24,MATCH($E$15,'Raw Pressure Data'!$1:$1,0))=-999,"",INDEX('Raw Pressure Data'!$A:$ZZ,ROW()-24,MATCH($E$15,'Raw Pressure Data'!$1:$1,0))+$F$15)),"") | Y26: =IFERROR(IF($E$16="","",IF(INDEX('Raw Pressure Data'!$A:$ZZ,ROW()-24,MATCH($E$16,'Raw Pressure Data'!$1:$1,0))=-999,"",INDEX('Raw Pressure Data'!$A:$ZZ,ROW()-24,MATCH($E$16,'Raw Pressure Data'!$1:$1,0))+$F$16)),"") | Z26: =IFERROR(IF($E$17="","",IF(INDEX('Raw Pressure Data'!$A:$ZZ,ROW()-24,MATCH($E$17,'Raw Pressure Data'!$1:$1,0))=-999,"",INDEX('Raw Pressure Data'!$A:$ZZ,ROW()-24,MATCH($E$17,'Raw Pressure Data'!$1:$1,0))+$F$17)),"") | AA26: =IFERROR(IF($E$18="","",IF(INDEX('Raw Pressure Data'!$A:$ZZ,ROW()-24,MATCH($E$18,'Raw Pressure Data'!$1:$1,0))=-999,"",INDEX('Raw Pressure Data'!$A:$ZZ,ROW()-24,MATCH($E$18,'Raw Pressure Data'!$1:$1,0))+$F$18)),"") | AB26: =IFERROR(IF($E$19="","",IF(INDEX('Raw Pressure Data'!$A:$ZZ,ROW()-24,MATCH($E$19,'Raw Pressure Data'!$1:$1,0))=-999,"",INDEX('Raw Pressure Data'!$A:$ZZ,ROW()-24,MATCH($E$19,'Raw Pressure Data'!$1:$1,0))+$F$19)),"") | AC26: =IFERROR(IF($E$20="","",IF(INDEX('Raw Pressure Data'!$A:$ZZ,ROW()-24,MATCH($E$20,'Raw Pressure Data'!$1:$1,0))=-999,"",INDEX('Raw Pressure Data'!$A:$ZZ,ROW()-24,MATCH($E$20,'Raw Pressure Data'!$1:$1,0))+$F$20)),"") | AD26: =IFERROR(IF($E$21="","",IF(INDEX('Raw Pressure Data'!$A:$ZZ,ROW()-24,MATCH($E$21,'Raw Pressure Data'!$1:$1,0))=-999,"",INDEX('Raw Pressure Data'!$A:$ZZ,ROW()-24,MATCH($E$21,'Raw Pressure Data'!$1:$1,0))+$F$21)),"") | AE26: =IFERROR(IF($E$22="","",IF(INDEX('Raw Pressure Data'!$A:$ZZ,ROW()-24,MATCH($E$22,'Raw Pressure Data'!$1:$1,0))=-999,"",INDEX('Raw Pressure Data'!$A:$ZZ,ROW()-24,MATCH($E$22,'Raw Pressure Data'!$1:$1,0))+$F$22)),"")
A27: =IFERROR(IF(INDEX('Raw Flow Data'!$A:$A,ROW()-24)="","",INDEX('Raw Flow Data'!$A:$A,ROW()-24)),"") | B27: =IFERROR(IF($B$3="","",IF(INDEX('Raw Flow Data'!$A:$ZZ,ROW()-24,MATCH($B$3,'Raw Flow Data'!$1:$1,0))=-999,"",INDEX('Raw Flow Data'!$A:$ZZ,ROW()-24,MATCH($B$3,'Raw Flow Data'!$1:$1,0))*$C$3)),"") | C27: =IFERROR(IF($B$4="","",IF(INDEX('Raw Flow Data'!$A:$ZZ,ROW()-24,MATCH($B$4,'Raw Flow Data'!$1:$1,0))=-999,"",INDEX('Raw Flow Data'!$A:$ZZ,ROW()-24,MATCH($B$4,'Raw Flow Data'!$1:$1,0))*$C$4)),"") | D27: =IFERROR(IF($B$5="","",IF(INDEX('Raw Flow Data'!$A:$ZZ,ROW()-24,MATCH($B$5,'Raw Flow Data'!$1:$1,0))=-999,"",INDEX('Raw Flow Data'!$A:$ZZ,ROW()-24,MATCH($B$5,'Raw Flow Data'!$1:$1,0))*$C$5)),"") | E27: =IFERROR(IF($B$6="","",IF(INDEX('Raw Flow Data'!$A:$ZZ,ROW()-24,MATCH($B$6,'Raw Flow Data'!$1:$1,0))=-999,"",INDEX('Raw Flow Data'!$A:$ZZ,ROW()-24,MATCH($B$6,'Raw Flow Data'!$1:$1,0))*$C$6)),"") | F27: =IFERROR(IF($B$7="","",IF(INDEX('Raw Flow Data'!$A:$ZZ,ROW()-24,MATCH($B$7,'Raw Flow Data'!$1:$1,0))=-999,"",INDEX('Raw Flow Data'!$A:$ZZ,ROW()-24,MATCH($B$7,'Raw Flow Data'!$1:$1,0))*$C$7)),"") | G27: =IFERROR(IF($B$8="","",IF(INDEX('Raw Flow Data'!$A:$ZZ,ROW()-24,MATCH($B$8,'Raw Flow Data'!$1:$1,0))=-999,"",INDEX('Raw Flow Data'!$A:$ZZ,ROW()-24,MATCH($B$8,'Raw Flow Data'!$1:$1,0))*$C$8)),"") | H27: =IFERROR(IF($B$9="","",IF(INDEX('Raw Flow Data'!$A:$ZZ,ROW()-24,MATCH($B$9,'Raw Flow Data'!$1:$1,0))=-999,"",INDEX('Raw Flow Data'!$A:$ZZ,ROW()-24,MATCH($B$9,'Raw Flow Data'!$1:$1,0))*$C$9)),"") | I27: =IFERROR(IF($B$10="","",IF(INDEX('Raw Flow Data'!$A:$ZZ,ROW()-24,MATCH($B$10,'Raw Flow Data'!$1:$1,0))=-999,"",INDEX('Raw Flow Data'!$A:$ZZ,ROW()-24,MATCH($B$10,'Raw Flow Data'!$1:$1,0))*$C$10)),"") | J27: =IFERROR(IF($B$11="","",IF(INDEX('Raw Flow Data'!$A:$ZZ,ROW()-24,MATCH($B$11,'Raw Flow Data'!$1:$1,0))=-999,"",INDEX('Raw Flow Data'!$A:$ZZ,ROW()-24,MATCH($B$11,'Raw Flow Data'!$1:$1,0))*$C$11)),"") | K27: =IFERROR(IF($B$12="","",IF(INDEX('Raw Flow Data'!$A:$ZZ,ROW()-24,MATCH($B$12,'Raw Flow Data'!$1:$1,0))=-999,"",INDEX('Raw Flow Data'!$A:$ZZ,ROW()-24,MATCH($B$12,'Raw Flow Data'!$1:$1,0))*$C$12)),"") | L27: =IFERROR(IF($E$3="","",IF(INDEX('Raw Pressure Data'!$A:$ZZ,ROW()-24,MATCH($E$3,'Raw Pressure Data'!$1:$1,0))=-999,"",INDEX('Raw Pressure Data'!$A:$ZZ,ROW()-24,MATCH($E$3,'Raw Pressure Data'!$1:$1,0))+$F$3)),"") | M27: =IFERROR(IF($E$4="","",IF(INDEX('Raw Pressure Data'!$A:$ZZ,ROW()-24,MATCH($E$4,'Raw Pressure Data'!$1:$1,0))=-999,"",INDEX('Raw Pressure Data'!$A:$ZZ,ROW()-24,MATCH($E$4,'Raw Pressure Data'!$1:$1,0))+$F$4)),"") | N27: =IFERROR(IF($E$5="","",IF(INDEX('Raw Pressure Data'!$A:$ZZ,ROW()-24,MATCH($E$5,'Raw Pressure Data'!$1:$1,0))=-999,"",INDEX('Raw Pressure Data'!$A:$ZZ,ROW()-24,MATCH($E$5,'Raw Pressure Data'!$1:$1,0))+$F$5)),"") | O27: =IFERROR(IF($E$6="","",IF(INDEX('Raw Pressure Data'!$A:$ZZ,ROW()-24,MATCH($E$6,'Raw Pressure Data'!$1:$1,0))=-999,"",INDEX('Raw Pressure Data'!$A:$ZZ,ROW()-24,MATCH($E$6,'Raw Pressure Data'!$1:$1,0))+$F$6)),"") | P27: =IFERROR(IF($E$7="","",IF(INDEX('Raw Pressure Data'!$A:$ZZ,ROW()-24,MATCH($E$7,'Raw Pressure Data'!$1:$1,0))=-999,"",INDEX('Raw Pressure Data'!$A:$ZZ,ROW()-24,MATCH($E$7,'Raw Pressure Data'!$1:$1,0))+$F$7)),"") | Q27: =IFERROR(IF($E$8="","",IF(INDEX('Raw Pressure Data'!$A:$ZZ,ROW()-24,MATCH($E$8,'Raw Pressure Data'!$1:$1,0))=-999,"",INDEX('Raw Pressure Data'!$A:$ZZ,ROW()-24,MATCH($E$8,'Raw Pressure Data'!$1:$1,0))+$F$8)),"") | R27: =IFERROR(IF($E$9="","",IF(INDEX('Raw Pressure Data'!$A:$ZZ,ROW()-24,MATCH($E$9,'Raw Pressure Data'!$1:$1,0))=-999,"",INDEX('Raw Pressure Data'!$A:$ZZ,ROW()-24,MATCH($E$9,'Raw Pressure Data'!$1:$1,0))+$F$9)),"") | S27: =IFERROR(IF($E$10="","",IF(INDEX('Raw Pressure Data'!$A:$ZZ,ROW()-24,MATCH($E$10,'Raw Pressure Data'!$1:$1,0))=-999,"",INDEX('Raw Pressure Data'!$A:$ZZ,ROW()-24,MATCH($E$10,'Raw Pressure Data'!$1:$1,0))+$F$10)),"") | T27: =IFERROR(IF($E$11="","",IF(INDEX('Raw Pressure Data'!$A:$ZZ,ROW()-24,MATCH($E$11,'Raw Pressure Data'!$1:$1,0))=-999,"",INDEX('Raw Pressure Data'!$A:$ZZ,ROW()-24,MATCH($E$11,'Raw Pressure Data'!$1:$1,0))+$F$11)),"") | U27: =IFERROR(IF($E$12="","",IF(INDEX('Raw Pressure Data'!$A:$ZZ,ROW()-24,MATCH($E$12,'Raw Pressure Data'!$1:$1,0))=-999,"",INDEX('Raw Pressure Data'!$A:$ZZ,ROW()-24,MATCH($E$12,'Raw Pressure Data'!$1:$1,0))+$F$12)),"") | V27: =IFERROR(IF($E$13="","",IF(INDEX('Raw Pressure Data'!$A:$ZZ,ROW()-24,MATCH($E$13,'Raw Pressure Data'!$1:$1,0))=-999,"",INDEX('Raw Pressure Data'!$A:$ZZ,ROW()-24,MATCH($E$13,'Raw Pressure Data'!$1:$1,0))+$F$13)),"") | W27: =IFERROR(IF($E$14="","",IF(INDEX('Raw Pressure Data'!$A:$ZZ,ROW()-24,MATCH($E$14,'Raw Pressure Data'!$1:$1,0))=-999,"",INDEX('Raw Pressure Data'!$A:$ZZ,ROW()-24,MATCH($E$14,'Raw Pressure Data'!$1:$1,0))+$F$14)),"") | X27: =IFERROR(IF($E$15="","",IF(INDEX('Raw Pressure Data'!$A:$ZZ,ROW()-24,MATCH($E$15,'Raw Pressure Data'!$1:$1,0))=-999,"",INDEX('Raw Pressure Data'!$A:$ZZ,ROW()-24,MATCH($E$15,'Raw Pressure Data'!$1:$1,0))+$F$15)),"") | Y27: =IFERROR(IF($E$16="","",IF(INDEX('Raw Pressure Data'!$A:$ZZ,ROW()-24,MATCH($E$16,'Raw Pressure Data'!$1:$1,0))=-999,"",INDEX('Raw Pressure Data'!$A:$ZZ,ROW()-24,MATCH($E$16,'Raw Pressure Data'!$1:$1,0))+$F$16)),"") | Z27: =IFERROR(IF($E$17="","",IF(INDEX('Raw Pressure Data'!$A:$ZZ,ROW()-24,MATCH($E$17,'Raw Pressure Data'!$1:$1,0))=-999,"",INDEX('Raw Pressure Data'!$A:$ZZ,ROW()-24,MATCH($E$17,'Raw Pressure Data'!$1:$1,0))+$F$17)),"") | AA27: =IFERROR(IF($E$18="","",IF(INDEX('Raw Pressure Data'!$A:$ZZ,ROW()-24,MATCH($E$18,'Raw Pressure Data'!$1:$1,0))=-999,"",INDEX('Raw Pressure Data'!$A:$ZZ,ROW()-24,MATCH($E$18,'Raw Pressure Data'!$1:$1,0))+$F$18)),"") | AB27: =IFERROR(IF($E$19="","",IF(INDEX('Raw Pressure Data'!$A:$ZZ,ROW()-24,MATCH($E$19,'Raw Pressure Data'!$1:$1,0))=-999,"",INDEX('Raw Pressure Data'!$A:$ZZ,ROW()-24,MATCH($E$19,'Raw Pressure Data'!$1:$1,0))+$F$19)),"") | AC27: =IFERROR(IF($E$20="","",IF(INDEX('Raw Pressure Data'!$A:$ZZ,ROW()-24,MATCH($E$20,'Raw Pressure Data'!$1:$1,0))=-999,"",INDEX('Raw Pressure Data'!$A:$ZZ,ROW()-24,MATCH($E$20,'Raw Pressure Data'!$1:$1,0))+$F$20)),"") | AD27: =IFERROR(IF($E$21="","",IF(INDEX('Raw Pressure Data'!$A:$ZZ,ROW()-24,MATCH($E$21,'Raw Pressure Data'!$1:$1,0))=-999,"",INDEX('Raw Pressure Data'!$A:$ZZ,ROW()-24,MATCH($E$21,'Raw Pressure Data'!$1:$1,0))+$F$21)),"") | AE27: =IFERROR(IF($E$22="","",IF(INDEX('Raw Pressure Data'!$A:$ZZ,ROW()-24,MATCH($E$22,'Raw Pressure Data'!$1:$1,0))=-999,"",INDEX('Raw Pressure Data'!$A:$ZZ,ROW()-24,MATCH($E$22,'Raw Pressure Data'!$1:$1,0))+$F$22)),"")
A28: =IFERROR(IF(INDEX('Raw Flow Data'!$A:$A,ROW()-24)="","",INDEX('Raw Flow Data'!$A:$A,ROW()-24)),"") | B28: =IFERROR(IF($B$3="","",IF(INDEX('Raw Flow Data'!$A:$ZZ,ROW()-24,MATCH($B$3,'Raw Flow Data'!$1:$1,0))=-999,"",INDEX('Raw Flow Data'!$A:$ZZ,ROW()-24,MATCH($B$3,'Raw Flow Data'!$1:$1,0))*$C$3)),"") | C28: =IFERROR(IF($B$4="","",IF(INDEX('Raw Flow Data'!$A:$ZZ,ROW()-24,MATCH($B$4,'Raw Flow Data'!$1:$1,0))=-999,"",INDEX('Raw Flow Data'!$A:$ZZ,ROW()-24,MATCH($B$4,'Raw Flow Data'!$1:$1,0))*$C$4)),"") | D28: =IFERROR(IF($B$5="","",IF(INDEX('Raw Flow Data'!$A:$ZZ,ROW()-24,MATCH($B$5,'Raw Flow Data'!$1:$1,0))=-999,"",INDEX('Raw Flow Data'!$A:$ZZ,ROW()-24,MATCH($B$5,'Raw Flow Data'!$1:$1,0))*$C$5)),"") | E28: =IFERROR(IF($B$6="","",IF(INDEX('Raw Flow Data'!$A:$ZZ,ROW()-24,MATCH($B$6,'Raw Flow Data'!$1:$1,0))=-999,"",INDEX('Raw Flow Data'!$A:$ZZ,ROW()-24,MATCH($B$6,'Raw Flow Data'!$1:$1,0))*$C$6)),"") | F28: =IFERROR(IF($B$7="","",IF(INDEX('Raw Flow Data'!$A:$ZZ,ROW()-24,MATCH($B$7,'Raw Flow Data'!$1:$1,0))=-999,"",INDEX('Raw Flow Data'!$A:$ZZ,ROW()-24,MATCH($B$7,'Raw Flow Data'!$1:$1,0))*$C$7)),"") | G28: =IFERROR(IF($B$8="","",IF(INDEX('Raw Flow Data'!$A:$ZZ,ROW()-24,MATCH($B$8,'Raw Flow Data'!$1:$1,0))=-999,"",INDEX('Raw Flow Data'!$A:$ZZ,ROW()-24,MATCH($B$8,'Raw Flow Data'!$1:$1,0))*$C$8)),"") | H28: =IFERROR(IF($B$9="","",IF(INDEX('Raw Flow Data'!$A:$ZZ,ROW()-24,MATCH($B$9,'Raw Flow Data'!$1:$1,0))=-999,"",INDEX('Raw Flow Data'!$A:$ZZ,ROW()-24,MATCH($B$9,'Raw Flow Data'!$1:$1,0))*$C$9)),"") | I28: =IFERROR(IF($B$10="","",IF(INDEX('Raw Flow Data'!$A:$ZZ,ROW()-24,MATCH($B$10,'Raw Flow Data'!$1:$1,0))=-999,"",INDEX('Raw Flow Data'!$A:$ZZ,ROW()-24,MATCH($B$10,'Raw Flow Data'!$1:$1,0))*$C$10)),"") | J28: =IFERROR(IF($B$11="","",IF(INDEX('Raw Flow Data'!$A:$ZZ,ROW()-24,MATCH($B$11,'Raw Flow Data'!$1:$1,0))=-999,"",INDEX('Raw Flow Data'!$A:$ZZ,ROW()-24,MATCH($B$11,'Raw Flow Data'!$1:$1,0))*$C$11)),"") | K28: =IFERROR(IF($B$12="","",IF(INDEX('Raw Flow Data'!$A:$ZZ,ROW()-24,MATCH($B$12,'Raw Flow Data'!$1:$1,0))=-999,"",INDEX('Raw Flow Data'!$A:$ZZ,ROW()-24,MATCH($B$12,'Raw Flow Data'!$1:$1,0))*$C$12)),"") | L28: =IFERROR(IF($E$3="","",IF(INDEX('Raw Pressure Data'!$A:$ZZ,ROW()-24,MATCH($E$3,'Raw Pressure Data'!$1:$1,0))=-999,"",INDEX('Raw Pressure Data'!$A:$ZZ,ROW()-24,MATCH($E$3,'Raw Pressure Data'!$1:$1,0))+$F$3)),"") | M28: =IFERROR(IF($E$4="","",IF(INDEX('Raw Pressure Data'!$A:$ZZ,ROW()-24,MATCH($E$4,'Raw Pressure Data'!$1:$1,0))=-999,"",INDEX('Raw Pressure Data'!$A:$ZZ,ROW()-24,MATCH($E$4,'Raw Pressure Data'!$1:$1,0))+$F$4)),"") | N28: =IFERROR(IF($E$5="","",IF(INDEX('Raw Pressure Data'!$A:$ZZ,ROW()-24,MATCH($E$5,'Raw Pressure Data'!$1:$1,0))=-999,"",INDEX('Raw Pressure Data'!$A:$ZZ,ROW()-24,MATCH($E$5,'Raw Pressure Data'!$1:$1,0))+$F$5)),"") | O28: =IFERROR(IF($E$6="","",IF(INDEX('Raw Pressure Data'!$A:$ZZ,ROW()-24,MATCH($E$6,'Raw Pressure Data'!$1:$1,0))=-999,"",INDEX('Raw Pressure Data'!$A:$ZZ,ROW()-24,MATCH($E$6,'Raw Pressure Data'!$1:$1,0))+$F$6)),"") | P28: =IFERROR(IF($E$7="","",IF(INDEX('Raw Pressure Data'!$A:$ZZ,ROW()-24,MATCH($E$7,'Raw Pressure Data'!$1:$1,0))=-999,"",INDEX('Raw Pressure Data'!$A:$ZZ,ROW()-24,MATCH($E$7,'Raw Pressure Data'!$1:$1,0))+$F$7)),"") | Q28: =IFERROR(IF($E$8="","",IF(INDEX('Raw Pressure Data'!$A:$ZZ,ROW()-24,MATCH($E$8,'Raw Pressure Data'!$1:$1,0))=-999,"",INDEX('Raw Pressure Data'!$A:$ZZ,ROW()-24,MATCH($E$8,'Raw Pressure Data'!$1:$1,0))+$F$8)),"") | R28: =IFERROR(IF($E$9="","",IF(INDEX('Raw Pressure Data'!$A:$ZZ,ROW()-24,MATCH($E$9,'Raw Pressure Data'!$1:$1,0))=-999,"",INDEX('Raw Pressure Data'!$A:$ZZ,ROW()-24,MATCH($E$9,'Raw Pressure Data'!$1:$1,0))+$F$9)),"") | S28: =IFERROR(IF($E$10="","",IF(INDEX('Raw Pressure Data'!$A:$ZZ,ROW()-24,MATCH($E$10,'Raw Pressure Data'!$1:$1,0))=-999,"",INDEX('Raw Pressure Data'!$A:$ZZ,ROW()-24,MATCH($E$10,'Raw Pressure Data'!$1:$1,0))+$F$10)),"") | T28: =IFERROR(IF($E$11="","",IF(INDEX('Raw Pressure Data'!$A:$ZZ,ROW()-24,MATCH($E$11,'Raw Pressure Data'!$1:$1,0))=-999,"",INDEX('Raw Pressure Data'!$A:$ZZ,ROW()-24,MATCH($E$11,'Raw Pressure Data'!$1:$1,0))+$F$11)),"") | U28: =IFERROR(IF($E$12="","",IF(INDEX('Raw Pressure Data'!$A:$ZZ,ROW()-24,MATCH($E$12,'Raw Pressure Data'!$1:$1,0))=-999,"",INDEX('Raw Pressure Data'!$A:$ZZ,ROW()-24,MATCH($E$12,'Raw Pressure Data'!$1:$1,0))+$F$12)),"") | V28: =IFERROR(IF($E$13="","",IF(INDEX('Raw Pressure Data'!$A:$ZZ,ROW()-24,MATCH($E$13,'Raw Pressure Data'!$1:$1,0))=-999,"",INDEX('Raw Pressure Data'!$A:$ZZ,ROW()-24,MATCH($E$13,'Raw Pressure Data'!$1:$1,0))+$F$13)),"") | W28: =IFERROR(IF($E$14="","",IF(INDEX('Raw Pressure Data'!$A:$ZZ,ROW()-24,MATCH($E$14,'Raw Pressure Data'!$1:$1,0))=-999,"",INDEX('Raw Pressure Data'!$A:$ZZ,ROW()-24,MATCH($E$14,'Raw Pressure Data'!$1:$1,0))+$F$14)),"") | X28: =IFERROR(IF($E$15="","",IF(INDEX('Raw Pressure Data'!$A:$ZZ,ROW()-24,MATCH($E$15,'Raw Pressure Data'!$1:$1,0))=-999,"",INDEX('Raw Pressure Data'!$A:$ZZ,ROW()-24,MATCH($E$15,'Raw Pressure Data'!$1:$1,0))+$F$15)),"") | Y28: =IFERROR(IF($E$16="","",IF(INDEX('Raw Pressure Data'!$A:$ZZ,ROW()-24,MATCH($E$16,'Raw Pressure Data'!$1:$1,0))=-999,"",INDEX('Raw Pressure Data'!$A:$ZZ,ROW()-24,MATCH($E$16,'Raw Pressure Data'!$1:$1,0))+$F$16)),"") | Z28: =IFERROR(IF($E$17="","",IF(INDEX('Raw Pressure Data'!$A:$ZZ,ROW()-24,MATCH($E$17,'Raw Pressure Data'!$1:$1,0))=-999,"",INDEX('Raw Pressure Data'!$A:$ZZ,ROW()-24,MATCH($E$17,'Raw Pressure Data'!$1:$1,0))+$F$17)),"") | AA28: =IFERROR(IF($E$18="","",IF(INDEX('Raw Pressure Data'!$A:$ZZ,ROW()-24,MATCH($E$18,'Raw Pressure Data'!$1:$1,0))=-999,"",INDEX('Raw Pressure Data'!$A:$ZZ,ROW()-24,MATCH($E$18,'Raw Pressure Data'!$1:$1,0))+$F$18)),"") | AB28: =IFERROR(IF($E$19="","",IF(INDEX('Raw Pressure Data'!$A:$ZZ,ROW()-24,MATCH($E$19,'Raw Pressure Data'!$1:$1,0))=-999,"",INDEX('Raw Pressure Data'!$A:$ZZ,ROW()-24,MATCH($E$19,'Raw Pressure Data'!$1:$1,0))+$F$19)),"") | AC28: =IFERROR(IF($E$20="","",IF(INDEX('Raw Pressure Data'!$A:$ZZ,ROW()-24,MATCH($E$20,'Raw Pressure Data'!$1:$1,0))=-999,"",INDEX('Raw Pressure Data'!$A:$ZZ,ROW()-24,MATCH($E$20,'Raw Pressure Data'!$1:$1,0))+$F$20)),"") | AD28: =IFERROR(IF($E$21="","",IF(INDEX('Raw Pressure Data'!$A:$ZZ,ROW()-24,MATCH($E$21,'Raw Pressure Data'!$1:$1,0))=-999,"",INDEX('Raw Pressure Data'!$A:$ZZ,ROW()-24,MATCH($E$21,'Raw Pressure Data'!$1:$1,0))+$F$21)),"") | AE28: =IFERROR(IF($E$22="","",IF(INDEX('Raw Pressure Data'!$A:$ZZ,ROW()-24,MATCH($E$22,'Raw Pressure Data'!$1:$1,0))=-999,"",INDEX('Raw Pressure Data'!$A:$ZZ,ROW()-24,MATCH($E$22,'Raw Pressure Data'!$1:$1,0))+$F$22)),"")
A29: =IFERROR(IF(INDEX('Raw Flow Data'!$A:$A,ROW()-24)="","",INDEX('Raw Flow Data'!$A:$A,ROW()-24)),"") | B29: =IFERROR(IF($B$3="","",IF(INDEX('Raw Flow Data'!$A:$ZZ,ROW()-24,MATCH($B$3,'Raw Flow Data'!$1:$1,0))=-999,"",INDEX('Raw Flow Data'!$A:$ZZ,ROW()-24,MATCH($B$3,'Raw Flow Data'!$1:$1,0))*$C$3)),"") | C29: =IFERROR(IF($B$4="","",IF(INDEX('Raw Flow Data'!$A:$ZZ,ROW()-24,MATCH($B$4,'Raw Flow Data'!$1:$1,0))=-999,"",INDEX('Raw Flow Data'!$A:$ZZ,ROW()-24,MATCH($B$4,'Raw Flow Data'!$1:$1,0))*$C$4)),"") | D29: =IFERROR(IF($B$5="","",IF(INDEX('Raw Flow Data'!$A:$ZZ,ROW()-24,MATCH($B$5,'Raw Flow Data'!$1:$1,0))=-999,"",INDEX('Raw Flow Data'!$A:$ZZ,ROW()-24,MATCH($B$5,'Raw Flow Data'!$1:$1,0))*$C$5)),"") | E29: =IFERROR(IF($B$6="","",IF(INDEX('Raw Flow Data'!$A:$ZZ,ROW()-24,MATCH($B$6,'Raw Flow Data'!$1:$1,0))=-999,"",INDEX('Raw Flow Data'!$A:$ZZ,ROW()-24,MATCH($B$6,'Raw Flow Data'!$1:$1,0))*$C$6)),"") | F29: =IFERROR(IF($B$7="","",IF(INDEX('Raw Flow Data'!$A:$ZZ,ROW()-24,MATCH($B$7,'Raw Flow Data'!$1:$1,0))=-999,"",INDEX('Raw Flow Data'!$A:$ZZ,ROW()-24,MATCH($B$7,'Raw Flow Data'!$1:$1,0))*$C$7)),"") | G29: =IFERROR(IF($B$8="","",IF(INDEX('Raw Flow Data'!$A:$ZZ,ROW()-24,MATCH($B$8,'Raw Flow Data'!$1:$1,0))=-999,"",INDEX('Raw Flow Data'!$A:$ZZ,ROW()-24,MATCH($B$8,'Raw Flow Data'!$1:$1,0))*$C$8)),"") | H29: =IFERROR(IF($B$9="","",IF(INDEX('Raw Flow Data'!$A:$ZZ,ROW()-24,MATCH($B$9,'Raw Flow Data'!$1:$1,0))=-999,"",INDEX('Raw Flow Data'!$A:$ZZ,ROW()-24,MATCH($B$9,'Raw Flow Data'!$1:$1,0))*$C$9)),"") | I29: =IFERROR(IF($B$10="","",IF(INDEX('Raw Flow Data'!$A:$ZZ,ROW()-24,MATCH($B$10,'Raw Flow Data'!$1:$1,0))=-999,"",INDEX('Raw Flow Data'!$A:$ZZ,ROW()-24,MATCH($B$10,'Raw Flow Data'!$1:$1,0))*$C$10)),"") | J29: =IFERROR(IF($B$11="","",IF(INDEX('Raw Flow Data'!$A:$ZZ,ROW()-24,MATCH($B$11,'Raw Flow Data'!$1:$1,0))=-999,"",INDEX('Raw Flow Data'!$A:$ZZ,ROW()-24,MATCH($B$11,'Raw Flow Data'!$1:$1,0))*$C$11)),"") | K29: =IFERROR(IF($B$12="","",IF(INDEX('Raw Flow Data'!$A:$ZZ,ROW()-24,MATCH($B$12,'Raw Flow Data'!$1:$1,0))=-999,"",INDEX('Raw Flow Data'!$A:$ZZ,ROW()-24,MATCH($B$12,'Raw Flow Data'!$1:$1,0))*$C$12)),"") | L29: =IFERROR(IF($E$3="","",IF(INDEX('Raw Pressure Data'!$A:$ZZ,ROW()-24,MATCH($E$3,'Raw Pressure Data'!$1:$1,0))=-999,"",INDEX('Raw Pressure Data'!$A:$ZZ,ROW()-24,MATCH($E$3,'Raw Pressure Data'!$1:$1,0))+$F$3)),"") | M29: =IFERROR(IF($E$4="","",IF(INDEX('Raw Pressure Data'!$A:$ZZ,ROW()-24,MATCH($E$4,'Raw Pressure Data'!$1:$1,0))=-999,"",INDEX('Raw Pressure Data'!$A:$ZZ,ROW()-24,MATCH($E$4,'Raw Pressure Data'!$1:$1,0))+$F$4)),"") | N29: =IFERROR(IF($E$5="","",IF(INDEX('Raw Pressure Data'!$A:$ZZ,ROW()-24,MATCH($E$5,'Raw Pressure Data'!$1:$1,0))=-999,"",INDEX('Raw Pressure Data'!$A:$ZZ,ROW()-24,MATCH($E$5,'Raw Pressure Data'!$1:$1,0))+$F$5)),"") | O29: =IFERROR(IF($E$6="","",IF(INDEX('Raw Pressure Data'!$A:$ZZ,ROW()-24,MATCH($E$6,'Raw Pressure Data'!$1:$1,0))=-999,"",INDEX('Raw Pressure Data'!$A:$ZZ,ROW()-24,MATCH($E$6,'Raw Pressure Data'!$1:$1,0))+$F$6)),"") | P29: =IFERROR(IF($E$7="","",IF(INDEX('Raw Pressure Data'!$A:$ZZ,ROW()-24,MATCH($E$7,'Raw Pressure Data'!$1:$1,0))=-999,"",INDEX('Raw Pressure Data'!$A:$ZZ,ROW()-24,MATCH($E$7,'Raw Pressure Data'!$1:$1,0))+$F$7)),"") | Q29: =IFERROR(IF($E$8="","",IF(INDEX('Raw Pressure Data'!$A:$ZZ,ROW()-24,MATCH($E$8,'Raw Pressure Data'!$1:$1,0))=-999,"",INDEX('Raw Pressure Data'!$A:$ZZ,ROW()-24,MATCH($E$8,'Raw Pressure Data'!$1:$1,0))+$F$8)),"") | R29: =IFERROR(IF($E$9="","",IF(INDEX('Raw Pressure Data'!$A:$ZZ,ROW()-24,MATCH($E$9,'Raw Pressure Data'!$1:$1,0))=-999,"",INDEX('Raw Pressure Data'!$A:$ZZ,ROW()-24,MATCH($E$9,'Raw Pressure Data'!$1:$1,0))+$F$9)),"") | S29: =IFERROR(IF($E$10="","",IF(INDEX('Raw Pressure Data'!$A:$ZZ,ROW()-24,MATCH($E$10,'Raw Pressure Data'!$1:$1,0))=-999,"",INDEX('Raw Pressure Data'!$A:$ZZ,ROW()-24,MATCH($E$10,'Raw Pressure Data'!$1:$1,0))+$F$10)),"") | T29: =IFERROR(IF($E$11="","",IF(INDEX('Raw Pressure Data'!$A:$ZZ,ROW()-24,MATCH($E$11,'Raw Pressure Data'!$1:$1,0))=-999,"",INDEX('Raw Pressure Data'!$A:$ZZ,ROW()-24,MATCH($E$11,'Raw Pressure Data'!$1:$1,0))+$F$11)),"") | U29: =IFERROR(IF($E$12="","",IF(INDEX('Raw Pressure Data'!$A:$ZZ,ROW()-24,MATCH($E$12,'Raw Pressure Data'!$1:$1,0))=-999,"",INDEX('Raw Pressure Data'!$A:$ZZ,ROW()-24,MATCH($E$12,'Raw Pressure Data'!$1:$1,0))+$F$12)),"") | V29: =IFERROR(IF($E$13="","",IF(INDEX('Raw Pressure Data'!$A:$ZZ,ROW()-24,MATCH($E$13,'Raw Pressure Data'!$1:$1,0))=-999,"",INDEX('Raw Pressure Data'!$A:$ZZ,ROW()-24,MATCH($E$13,'Raw Pressure Data'!$1:$1,0))+$F$13)),"") | W29: =IFERROR(IF($E$14="","",IF(INDEX('Raw Pressure Data'!$A:$ZZ,ROW()-24,MATCH($E$14,'Raw Pressure Data'!$1:$1,0))=-999,"",INDEX('Raw Pressure Data'!$A:$ZZ,ROW()-24,MATCH($E$14,'Raw Pressure Data'!$1:$1,0))+$F$14)),"") | X29: =IFERROR(IF($E$15="","",IF(INDEX('Raw Pressure Data'!$A:$ZZ,ROW()-24,MATCH($E$15,'Raw Pressure Data'!$1:$1,0))=-999,"",INDEX('Raw Pressure Data'!$A:$ZZ,ROW()-24,MATCH($E$15,'Raw Pressure Data'!$1:$1,0))+$F$15)),"") | Y29: =IFERROR(IF($E$16="","",IF(INDEX('Raw Pressure Data'!$A:$ZZ,ROW()-24,MATCH($E$16,'Raw Pressure Data'!$1:$1,0))=-999,"",INDEX('Raw Pressure Data'!$A:$ZZ,ROW()-24,MATCH($E$16,'Raw Pressure Data'!$1:$1,0))+$F$16)),"") | Z29: =IFERROR(IF($E$17="","",IF(INDEX('Raw Pressure Data'!$A:$ZZ,ROW()-24,MATCH($E$17,'Raw Pressure Data'!$1:$1,0))=-999,"",INDEX('Raw Pressure Data'!$A:$ZZ,ROW()-24,MATCH($E$17,'Raw Pressure Data'!$1:$1,0))+$F$17)),"") | AA29: =IFERROR(IF($E$18="","",IF(INDEX('Raw Pressure Data'!$A:$ZZ,ROW()-24,MATCH($E$18,'Raw Pressure Data'!$1:$1,0))=-999,"",INDEX('Raw Pressure Data'!$A:$ZZ,ROW()-24,MATCH($E$18,'Raw Pressure Data'!$1:$1,0))+$F$18)),"") | AB29: =IFERROR(IF($E$19="","",IF(INDEX('Raw Pressure Data'!$A:$ZZ,ROW()-24,MATCH($E$19,'Raw Pressure Data'!$1:$1,0))=-999,"",INDEX('Raw Pressure Data'!$A:$ZZ,ROW()-24,MATCH($E$19,'Raw Pressure Data'!$1:$1,0))+$F$19)),"") | AC29: =IFERROR(IF($E$20="","",IF(INDEX('Raw Pressure Data'!$A:$ZZ,ROW()-24,MATCH($E$20,'Raw Pressure Data'!$1:$1,0))=-999,"",INDEX('Raw Pressure Data'!$A:$ZZ,ROW()-24,MATCH($E$20,'Raw Pressure Data'!$1:$1,0))+$F$20)),"") | AD29: =IFERROR(IF($E$21="","",IF(INDEX('Raw Pressure Data'!$A:$ZZ,ROW()-24,MATCH($E$21,'Raw Pressure Data'!$1:$1,0))=-999,"",INDEX('Raw Pressure Data'!$A:$ZZ,ROW()-24,MATCH($E$21,'Raw Pressure Data'!$1:$1,0))+$F$21)),"") | AE29: =IFERROR(IF($E$22="","",IF(INDEX('Raw Pressure Data'!$A:$ZZ,ROW()-24,MATCH($E$22,'Raw Pressure Data'!$1:$1,0))=-999,"",INDEX('Raw Pressure Data'!$A:$ZZ,ROW()-24,MATCH($E$22,'Raw Pressure Data'!$1:$1,0))+$F$22)),"")
A30: =IFERROR(IF(INDEX('Raw Flow Data'!$A:$A,ROW()-24)="","",INDEX('Raw Flow Data'!$A:$A,ROW()-24)),"") | B30: =IFERROR(IF($B$3="","",IF(INDEX('Raw Flow Data'!$A:$ZZ,ROW()-24,MATCH($B$3,'Raw Flow Data'!$1:$1,0))=-999,"",INDEX('Raw Flow Data'!$A:$ZZ,ROW()-24,MATCH($B$3,'Raw Flow Data'!$1:$1,0))*$C$3)),"") | C30: =IFERROR(IF($B$4="","",IF(INDEX('Raw Flow Data'!$A:$ZZ,ROW()-24,MATCH($B$4,'Raw Flow Data'!$1:$1,0))=-999,"",INDEX('Raw Flow Data'!$A:$ZZ,ROW()-24,MATCH($B$4,'Raw Flow Data'!$1:$1,0))*$C$4)),"") | D30: =IFERROR(IF($B$5="","",IF(INDEX('Raw Flow Data'!$A:$ZZ,ROW()-24,MATCH($B$5,'Raw Flow Data'!$1:$1,0))=-999,"",INDEX('Raw Flow Data'!$A:$ZZ,ROW()-24,MATCH($B$5,'Raw Flow Data'!$1:$1,0))*$C$5)),"") | E30: =IFERROR(IF($B$6="","",IF(INDEX('Raw Flow Data'!$A:$ZZ,ROW()-24,MATCH($B$6,'Raw Flow Data'!$1:$1,0))=-999,"",INDEX('Raw Flow Data'!$A:$ZZ,ROW()-24,MATCH($B$6,'Raw Flow Data'!$1:$1,0))*$C$6)),"") | F30: =IFERROR(IF($B$7="","",IF(INDEX('Raw Flow Data'!$A:$ZZ,ROW()-24,MATCH($B$7,'Raw Flow Data'!$1:$1,0))=-999,"",INDEX('Raw Flow Data'!$A:$ZZ,ROW()-24,MATCH($B$7,'Raw Flow Data'!$1:$1,0))*$C$7)),"") | G30: =IFERROR(IF($B$8="","",IF(INDEX('Raw Flow Data'!$A:$ZZ,ROW()-24,MATCH($B$8,'Raw Flow Data'!$1:$1,0))=-999,"",INDEX('Raw Flow Data'!$A:$ZZ,ROW()-24,MATCH($B$8,'Raw Flow Data'!$1:$1,0))*$C$8)),"") | H30: =IFERROR(IF($B$9="","",IF(INDEX('Raw Flow Data'!$A:$ZZ,ROW()-24,MATCH($B$9,'Raw Flow Data'!$1:$1,0))=-999,"",INDEX('Raw Flow Data'!$A:$ZZ,ROW()-24,MATCH($B$9,'Raw Flow Data'!$1:$1,0))*$C$9)),"") | I30: =IFERROR(IF($B$10="","",IF(INDEX('Raw Flow Data'!$A:$ZZ,ROW()-24,MATCH($B$10,'Raw Flow Data'!$1:$1,0))=-999,"",INDEX('Raw Flow Data'!$A:$ZZ,ROW()-24,MATCH($B$10,'Raw Flow Data'!$1:$1,0))*$C$10)),"") | J30: =IFERROR(IF($B$11="","",IF(INDEX('Raw Flow Data'!$A:$ZZ,ROW()-24,MATCH($B$11,'Raw Flow Data'!$1:$1,0))=-999,"",INDEX('Raw Flow Data'!$A:$ZZ,ROW()-24,MATCH($B$11,'Raw Flow Data'!$1:$1,0))*$C$11)),"") | K30: =IFERROR(IF($B$12="","",IF(INDEX('Raw Flow Data'!$A:$ZZ,ROW()-24,MATCH($B$12,'Raw Flow Data'!$1:$1,0))=-999,"",INDEX('Raw Flow Data'!$A:$ZZ,ROW()-24,MATCH($B$12,'Raw Flow Data'!$1:$1,0))*$C$12)),"") | L30: =IFERROR(IF($E$3="","",IF(INDEX('Raw Pressure Data'!$A:$ZZ,ROW()-24,MATCH($E$3,'Raw Pressure Data'!$1:$1,0))=-999,"",INDEX('Raw Pressure Data'!$A:$ZZ,ROW()-24,MATCH($E$3,'Raw Pressure Data'!$1:$1,0))+$F$3)),"") | M30: =IFERROR(IF($E$4="","",IF(INDEX('Raw Pressure Data'!$A:$ZZ,ROW()-24,MATCH($E$4,'Raw Pressure Data'!$1:$1,0))=-999,"",INDEX('Raw Pressure Data'!$A:$ZZ,ROW()-24,MATCH($E$4,'Raw Pressure Data'!$1:$1,0))+$F$4)),"") | N30: =IFERROR(IF($E$5="","",IF(INDEX('Raw Pressure Data'!$A:$ZZ,ROW()-24,MATCH($E$5,'Raw Pressure Data'!$1:$1,0))=-999,"",INDEX('Raw Pressure Data'!$A:$ZZ,ROW()-24,MATCH($E$5,'Raw Pressure Data'!$1:$1,0))+$F$5)),"") | O30: =IFERROR(IF($E$6="","",IF(INDEX('Raw Pressure Data'!$A:$ZZ,ROW()-24,MATCH($E$6,'Raw Pressure Data'!$1:$1,0))=-999,"",INDEX('Raw Pressure Data'!$A:$ZZ,ROW()-24,MATCH($E$6,'Raw Pressure Data'!$1:$1,0))+$F$6)),"") | P30: =IFERROR(IF($E$7="","",IF(INDEX('Raw Pressure Data'!$A:$ZZ,ROW()-24,MATCH($E$7,'Raw Pressure Data'!$1:$1,0))=-999,"",INDEX('Raw Pressure Data'!$A:$ZZ,ROW()-24,MATCH($E$7,'Raw Pressure Data'!$1:$1,0))+$F$7)),"") | Q30: =IFERROR(IF($E$8="","",IF(INDEX('Raw Pressure Data'!$A:$ZZ,ROW()-24,MATCH($E$8,'Raw Pressure Data'!$1:$1,0))=-999,"",INDEX('Raw Pressure Data'!$A:$ZZ,ROW()-24,MATCH($E$8,'Raw Pressure Data'!$1:$1,0))+$F$8)),"") | R30: =IFERROR(IF($E$9="","",IF(INDEX('Raw Pressure Data'!$A:$ZZ,ROW()-24,MATCH($E$9,'Raw Pressure Data'!$1:$1,0))=-999,"",INDEX('Raw Pressure Data'!$A:$ZZ,ROW()-24,MATCH($E$9,'Raw Pressure Data'!$1:$1,0))+$F$9)),"") | S30: =IFERROR(IF($E$10="","",IF(INDEX('Raw Pressure Data'!$A:$ZZ,ROW()-24,MATCH($E$10,'Raw Pressure Data'!$1:$1,0))=-999,"",INDEX('Raw Pressure Data'!$A:$ZZ,ROW()-24,MATCH($E$10,'Raw Pressure Data'!$1:$1,0))+$F$10)),"") | T30: =IFERROR(IF($E$11="","",IF(INDEX('Raw Pressure Data'!$A:$ZZ,ROW()-24,MATCH($E$11,'Raw Pressure Data'!$1:$1,0))=-999,"",INDEX('Raw Pressure Data'!$A:$ZZ,ROW()-24,MATCH($E$11,'Raw Pressure Data'!$1:$1,0))+$F$11)),"") | U30: =IFERROR(IF($E$12="","",IF(INDEX('Raw Pressure Data'!$A:$ZZ,ROW()-24,MATCH($E$12,'Raw Pressure Data'!$1:$1,0))=-999,"",INDEX('Raw Pressure Data'!$A:$ZZ,ROW()-24,MATCH($E$12,'Raw Pressure Data'!$1:$1,0))+$F$12)),"") | V30: =IFERROR(IF($E$13="","",IF(INDEX('Raw Pressure Data'!$A:$ZZ,ROW()-24,MATCH($E$13,'Raw Pressure Data'!$1:$1,0))=-999,"",INDEX('Raw Pressure Data'!$A:$ZZ,ROW()-24,MATCH($E$13,'Raw Pressure Data'!$1:$1,0))+$F$13)),"") | W30: =IFERROR(IF($E$14="","",IF(INDEX('Raw Pressure Data'!$A:$ZZ,ROW()-24,MATCH($E$14,'Raw Pressure Data'!$1:$1,0))=-999,"",INDEX('Raw Pressure Data'!$A:$ZZ,ROW()-24,MATCH($E$14,'Raw Pressure Data'!$1:$1,0))+$F$14)),"") | X30: =IFERROR(IF($E$15="","",IF(INDEX('Raw Pressure Data'!$A:$ZZ,ROW()-24,MATCH($E$15,'Raw Pressure Data'!$1:$1,0))=-999,"",INDEX('Raw Pressure Data'!$A:$ZZ,ROW()-24,MATCH($E$15,'Raw Pressure Data'!$1:$1,0))+$F$15)),"") | Y30: =IFERROR(IF($E$16="","",IF(INDEX('Raw Pressure Data'!$A:$ZZ,ROW()-24,MATCH($E$16,'Raw Pressure Data'!$1:$1,0))=-999,"",INDEX('Raw Pressure Data'!$A:$ZZ,ROW()-24,MATCH($E$16,'Raw Pressure Data'!$1:$1,0))+$F$16)),"") | Z30: =IFERROR(IF($E$17="","",IF(INDEX('Raw Pressure Data'!$A:$ZZ,ROW()-24,MATCH($E$17,'Raw Pressure Data'!$1:$1,0))=-999,"",INDEX('Raw Pressure Data'!$A:$ZZ,ROW()-24,MATCH($E$17,'Raw Pressure Data'!$1:$1,0))+$F$17)),"") | AA30: =IFERROR(IF($E$18="","",IF(INDEX('Raw Pressure Data'!$A:$ZZ,ROW()-24,MATCH($E$18,'Raw Pressure Data'!$1:$1,0))=-999,"",INDEX('Raw Pressure Data'!$A:$ZZ,ROW()-24,MATCH($E$18,'Raw Pressure Data'!$1:$1,0))+$F$18)),"") | AB30: =IFERROR(IF($E$19="","",IF(INDEX('Raw Pressure Data'!$A:$ZZ,ROW()-24,MATCH($E$19,'Raw Pressure Data'!$1:$1,0))=-999,"",INDEX('Raw Pressure Data'!$A:$ZZ,ROW()-24,MATCH($E$19,'Raw Pressure Data'!$1:$1,0))+$F$19)),"") | AC30: =IFERROR(IF($E$20="","",IF(INDEX('Raw Pressure Data'!$A:$ZZ,ROW()-24,MATCH($E$20,'Raw Pressure Data'!$1:$1,0))=-999,"",INDEX('Raw Pressure Data'!$A:$ZZ,ROW()-24,MATCH($E$20,'Raw Pressure Data'!$1:$1,0))+$F$20)),"") | AD30: =IFERROR(IF($E$21="","",IF(INDEX('Raw Pressure Data'!$A:$ZZ,ROW()-24,MATCH($E$21,'Raw Pressure Data'!$1:$1,0))=-999,"",INDEX('Raw Pressure Data'!$A:$ZZ,ROW()-24,MATCH($E$21,'Raw Pressure Data'!$1:$1,0))+$F$21)),"") | AE30: =IFERROR(IF($E$22="","",IF(INDEX('Raw Pressure Data'!$A:$ZZ,ROW()-24,MATCH($E$22,'Raw Pressure Data'!$1:$1,0))=-999,"",INDEX('Raw Pressure Data'!$A:$ZZ,ROW()-24,MATCH($E$22,'Raw Pressure Data'!$1:$1,0))+$F$22)),"")
A31: =IFERROR(IF(INDEX('Raw Flow Data'!$A:$A,ROW()-24)="","",INDEX('Raw Flow Data'!$A:$A,ROW()-24)),"") | B31: =IFERROR(IF($B$3="","",IF(INDEX('Raw Flow Data'!$A:$ZZ,ROW()-24,MATCH($B$3,'Raw Flow Data'!$1:$1,0))=-999,"",INDEX('Raw Flow Data'!$A:$ZZ,ROW()-24,MATCH($B$3,'Raw Flow Data'!$1:$1,0))*$C$3)),"") | C31: =IFERROR(IF($B$4="","",IF(INDEX('Raw Flow Data'!$A:$ZZ,ROW()-24,MATCH($B$4,'Raw Flow Data'!$1:$1,0))=-999,"",INDEX('Raw Flow Data'!$A:$ZZ,ROW()-24,MATCH($B$4,'Raw Flow Data'!$1:$1,0))*$C$4)),"") | D31: =IFERROR(IF($B$5="","",IF(INDEX('Raw Flow Data'!$A:$ZZ,ROW()-24,MATCH($B$5,'Raw Flow Data'!$1:$1,0))=-999,"",INDEX('Raw Flow Data'!$A:$ZZ,ROW()-24,MATCH($B$5,'Raw Flow Data'!$1:$1,0))*$C$5)),"") | E31: =IFERROR(IF($B$6="","",IF(INDEX('Raw Flow Data'!$A:$ZZ,ROW()-24,MATCH($B$6,'Raw Flow Data'!$1:$1,0))=-999,"",INDEX('Raw Flow Data'!$A:$ZZ,ROW()-24,MATCH($B$6,'Raw Flow Data'!$1:$1,0))*$C$6)),"") | F31: =IFERROR(IF($B$7="","",IF(INDEX('Raw Flow Data'!$A:$ZZ,ROW()-24,MATCH($B$7,'Raw Flow Data'!$1:$1,0))=-999,"",INDEX('Raw Flow Data'!$A:$ZZ,ROW()-24,MATCH($B$7,'Raw Flow Data'!$1:$1,0))*$C$7)),"") | G31: =IFERROR(IF($B$8="","",IF(INDEX('Raw Flow Data'!$A:$ZZ,ROW()-24,MATCH($B$8,'Raw Flow Data'!$1:$1,0))=-999,"",INDEX('Raw Flow Data'!$A:$ZZ,ROW()-24,MATCH($B$8,'Raw Flow Data'!$1:$1,0))*$C$8)),"") | H31: =IFERROR(IF($B$9="","",IF(INDEX('Raw Flow Data'!$A:$ZZ,ROW()-24,MATCH($B$9,'Raw Flow Data'!$1:$1,0))=-999,"",INDEX('Raw Flow Data'!$A:$ZZ,ROW()-24,MATCH($B$9,'Raw Flow Data'!$1:$1,0))*$C$9)),"") | I31: =IFERROR(IF($B$10="","",IF(INDEX('Raw Flow Data'!$A:$ZZ,ROW()-24,MATCH($B$10,'Raw Flow Data'!$1:$1,0))=-999,"",INDEX('Raw Flow Data'!$A:$ZZ,ROW()-24,MATCH($B$10,'Raw Flow Data'!$1:$1,0))*$C$10)),"") | J31: =IFERROR(IF($B$11="","",IF(INDEX('Raw Flow Data'!$A:$ZZ,ROW()-24,MATCH($B$11,'Raw Flow Data'!$1:$1,0))=-999,"",INDEX('Raw Flow Data'!$A:$ZZ,ROW()-24,MATCH($B$11,'Raw Flow Data'!$1:$1,0))*$C$11)),"") | K31: =IFERROR(IF($B$12="","",IF(INDEX('Raw Flow Data'!$A:$ZZ,ROW()-24,MATCH($B$12,'Raw Flow Data'!$1:$1,0))=-999,"",INDEX('Raw Flow Data'!$A:$ZZ,ROW()-24,MATCH($B$12,'Raw Flow Data'!$1:$1,0))*$C$12)),"") | L31: =IFERROR(IF($E$3="","",IF(INDEX('Raw Pressure Data'!$A:$ZZ,ROW()-24,MATCH($E$3,'Raw Pressure Data'!$1:$1,0))=-999,"",INDEX('Raw Pressure Data'!$A:$ZZ,ROW()-24,MATCH($E$3,'Raw Pressure Data'!$1:$1,0))+$F$3)),"") | M31: =IFERROR(IF($E$4="","",IF(INDEX('Raw Pressure Data'!$A:$ZZ,ROW()-24,MATCH($E$4,'Raw Pressure Data'!$1:$1,0))=-999,"",INDEX('Raw Pressure Data'!$A:$ZZ,ROW()-24,MATCH($E$4,'Raw Pressure Data'!$1:$1,0))+$F$4)),"") | N31: =IFERROR(IF($E$5="","",IF(INDEX('Raw Pressure Data'!$A:$ZZ,ROW()-24,MATCH($E$5,'Raw Pressure Data'!$1:$1,0))=-999,"",INDEX('Raw Pressure Data'!$A:$ZZ,ROW()-24,MATCH($E$5,'Raw Pressure Data'!$1:$1,0))+$F$5)),"") | O31: =IFERROR(IF($E$6="","",IF(INDEX('Raw Pressure Data'!$A:$ZZ,ROW()-24,MATCH($E$6,'Raw Pressure Data'!$1:$1,0))=-999,"",INDEX('Raw Pressure Data'!$A:$ZZ,ROW()-24,MATCH($E$6,'Raw Pressure Data'!$1:$1,0))+$F$6)),"") | P31: =IFERROR(IF($E$7="","",IF(INDEX('Raw Pressure Data'!$A:$ZZ,ROW()-24,MATCH($E$7,'Raw Pressure Data'!$1:$1,0))=-999,"",INDEX('Raw Pressure Data'!$A:$ZZ,ROW()-24,MATCH($E$7,'Raw Pressure Data'!$1:$1,0))+$F$7)),"") | Q31: =IFERROR(IF($E$8="","",IF(INDEX('Raw Pressure Data'!$A:$ZZ,ROW()-24,MATCH($E$8,'Raw Pressure Data'!$1:$1,0))=-999,"",INDEX('Raw Pressure Data'!$A:$ZZ,ROW()-24,MATCH($E$8,'Raw Pressure Data'!$1:$1,0))+$F$8)),"") | R31: =IFERROR(IF($E$9="","",IF(INDEX('Raw Pressure Data'!$A:$ZZ,ROW()-24,MATCH($E$9,'Raw Pressure Data'!$1:$1,0))=-999,"",INDEX('Raw Pressure Data'!$A:$ZZ,ROW()-24,MATCH($E$9,'Raw Pressure Data'!$1:$1,0))+$F$9)),"") | S31: =IFERROR(IF($E$10="","",IF(INDEX('Raw Pressure Data'!$A:$ZZ,ROW()-24,MATCH($E$10,'Raw Pressure Data'!$1:$1,0))=-999,"",INDEX('Raw Pressure Data'!$A:$ZZ,ROW()-24,MATCH($E$10,'Raw Pressure Data'!$1:$1,0))+$F$10)),"") | T31: =IFERROR(IF($E$11="","",IF(INDEX('Raw Pressure Data'!$A:$ZZ,ROW()-24,MATCH($E$11,'Raw Pressure Data'!$1:$1,0))=-999,"",INDEX('Raw Pressure Data'!$A:$ZZ,ROW()-24,MATCH($E$11,'Raw Pressure Data'!$1:$1,0))+$F$11)),"") | U31: =IFERROR(IF($E$12="","",IF(INDEX('Raw Pressure Data'!$A:$ZZ,ROW()-24,MATCH($E$12,'Raw Pressure Data'!$1:$1,0))=-999,"",INDEX('Raw Pressure Data'!$A:$ZZ,ROW()-24,MATCH($E$12,'Raw Pressure Data'!$1:$1,0))+$F$12)),"") | V31: =IFERROR(IF($E$13="","",IF(INDEX('Raw Pressure Data'!$A:$ZZ,ROW()-24,MATCH($E$13,'Raw Pressure Data'!$1:$1,0))=-999,"",INDEX('Raw Pressure Data'!$A:$ZZ,ROW()-24,MATCH($E$13,'Raw Pressure Data'!$1:$1,0))+$F$13)),"") | W31: =IFERROR(IF($E$14="","",IF(INDEX('Raw Pressure Data'!$A:$ZZ,ROW()-24,MATCH($E$14,'Raw Pressure Data'!$1:$1,0))=-999,"",INDEX('Raw Pressure Data'!$A:$ZZ,ROW()-24,MATCH($E$14,'Raw Pressure Data'!$1:$1,0))+$F$14)),"") | X31: =IFERROR(IF($E$15="","",IF(INDEX('Raw Pressure Data'!$A:$ZZ,ROW()-24,MATCH($E$15,'Raw Pressure Data'!$1:$1,0))=-999,"",INDEX('Raw Pressure Data'!$A:$ZZ,ROW()-24,MATCH($E$15,'Raw Pressure Data'!$1:$1,0))+$F$15)),"") | Y31: =IFERROR(IF($E$16="","",IF(INDEX('Raw Pressure Data'!$A:$ZZ,ROW()-24,MATCH($E$16,'Raw Pressure Data'!$1:$1,0))=-999,"",INDEX('Raw Pressure Data'!$A:$ZZ,ROW()-24,MATCH($E$16,'Raw Pressure Data'!$1:$1,0))+$F$16)),"") | Z31: =IFERROR(IF($E$17="","",IF(INDEX('Raw Pressure Data'!$A:$ZZ,ROW()-24,MATCH($E$17,'Raw Pressure Data'!$1:$1,0))=-999,"",INDEX('Raw Pressure Data'!$A:$ZZ,ROW()-24,MATCH($E$17,'Raw Pressure Data'!$1:$1,0))+$F$17)),"") | AA31: =IFERROR(IF($E$18="","",IF(INDEX('Raw Pressure Data'!$A:$ZZ,ROW()-24,MATCH($E$18,'Raw Pressure Data'!$1:$1,0))=-999,"",INDEX('Raw Pressure Data'!$A:$ZZ,ROW()-24,MATCH($E$18,'Raw Pressure Data'!$1:$1,0))+$F$18)),"") | AB31: =IFERROR(IF($E$19="","",IF(INDEX('Raw Pressure Data'!$A:$ZZ,ROW()-24,MATCH($E$19,'Raw Pressure Data'!$1:$1,0))=-999,"",INDEX('Raw Pressure Data'!$A:$ZZ,ROW()-24,MATCH($E$19,'Raw Pressure Data'!$1:$1,0))+$F$19)),"") | AC31: =IFERROR(IF($E$20="","",IF(INDEX('Raw Pressure Data'!$A:$ZZ,ROW()-24,MATCH($E$20,'Raw Pressure Data'!$1:$1,0))=-999,"",INDEX('Raw Pressure Data'!$A:$ZZ,ROW()-24,MATCH($E$20,'Raw Pressure Data'!$1:$1,0))+$F$20)),"") | AD31: =IFERROR(IF($E$21="","",IF(INDEX('Raw Pressure Data'!$A:$ZZ,ROW()-24,MATCH($E$21,'Raw Pressure Data'!$1:$1,0))=-999,"",INDEX('Raw Pressure Data'!$A:$ZZ,ROW()-24,MATCH($E$21,'Raw Pressure Data'!$1:$1,0))+$F$21)),"") | AE31: =IFERROR(IF($E$22="","",IF(INDEX('Raw Pressure Data'!$A:$ZZ,ROW()-24,MATCH($E$22,'Raw Pressure Data'!$1:$1,0))=-999,"",INDEX('Raw Pressure Data'!$A:$ZZ,ROW()-24,MATCH($E$22,'Raw Pressure Data'!$1:$1,0))+$F$22)),"")
A32: =IFERROR(IF(INDEX('Raw Flow Data'!$A:$A,ROW()-24)="","",INDEX('Raw Flow Data'!$A:$A,ROW()-24)),"") | B32: =IFERROR(IF($B$3="","",IF(INDEX('Raw Flow Data'!$A:$ZZ,ROW()-24,MATCH($B$3,'Raw Flow Data'!$1:$1,0))=-999,"",INDEX('Raw Flow Data'!$A:$ZZ,ROW()-24,MATCH($B$3,'Raw Flow Data'!$1:$1,0))*$C$3)),"") | C32: =IFERROR(IF($B$4="","",IF(INDEX('Raw Flow Data'!$A:$ZZ,ROW()-24,MATCH($B$4,'Raw Flow Data'!$1:$1,0))=-999,"",INDEX('Raw Flow Data'!$A:$ZZ,ROW()-24,MATCH($B$4,'Raw Flow Data'!$1:$1,0))*$C$4)),"") | D32: =IFERROR(IF($B$5="","",IF(INDEX('Raw Flow Data'!$A:$ZZ,ROW()-24,MATCH($B$5,'Raw Flow Data'!$1:$1,0))=-999,"",INDEX('Raw Flow Data'!$A:$ZZ,ROW()-24,MATCH($B$5,'Raw Flow Data'!$1:$1,0))*$C$5)),"") | E32: =IFERROR(IF($B$6="","",IF(INDEX('Raw Flow Data'!$A:$ZZ,ROW()-24,MATCH($B$6,'Raw Flow Data'!$1:$1,0))=-999,"",INDEX('Raw Flow Data'!$A:$ZZ,ROW()-24,MATCH($B$6,'Raw Flow Data'!$1:$1,0))*$C$6)),"") | F32: =IFERROR(IF($B$7="","",IF(INDEX('Raw Flow Data'!$A:$ZZ,ROW()-24,MATCH($B$7,'Raw Flow Data'!$1:$1,0))=-999,"",INDEX('Raw Flow Data'!$A:$ZZ,ROW()-24,MATCH($B$7,'Raw Flow Data'!$1:$1,0))*$C$7)),"") | G32: =IFERROR(IF($B$8="","",IF(INDEX('Raw Flow Data'!$A:$ZZ,ROW()-24,MATCH($B$8,'Raw Flow Data'!$1:$1,0))=-999,"",INDEX('Raw Flow Data'!$A:$ZZ,ROW()-24,MATCH($B$8,'Raw Flow Data'!$1:$1,0))*$C$8)),"") | H32: =IFERROR(IF($B$9="","",IF(INDEX('Raw Flow Data'!$A:$ZZ,ROW()-24,MATCH($B$9,'Raw Flow Data'!$1:$1,0))=-999,"",INDEX('Raw Flow Data'!$A:$ZZ,ROW()-24,MATCH($B$9,'Raw Flow Data'!$1:$1,0))*$C$9)),"") | I32: =IFERROR(IF($B$10="","",IF(INDEX('Raw Flow Data'!$A:$ZZ,ROW()-24,MATCH($B$10,'Raw Flow Data'!$1:$1,0))=-999,"",INDEX('Raw Flow Data'!$A:$ZZ,ROW()-24,MATCH($B$10,'Raw Flow Data'!$1:$1,0))*$C$10)),"") | J32: =IFERROR(IF($B$11="","",IF(INDEX('Raw Flow Data'!$A:$ZZ,ROW()-24,MATCH($B$11,'Raw Flow Data'!$1:$1,0))=-999,"",INDEX('Raw Flow Data'!$A:$ZZ,ROW()-24,MATCH($B$11,'Raw Flow Data'!$1:$1,0))*$C$11)),"") | K32: =IFERROR(IF($B$12="","",IF(INDEX('Raw Flow Data'!$A:$ZZ,ROW()-24,MATCH($B$12,'Raw Flow Data'!$1:$1,0))=-999,"",INDEX('Raw Flow Data'!$A:$ZZ,ROW()-24,MATCH($B$12,'Raw Flow Data'!$1:$1,0))*$C$12)),"") | L32: =IFERROR(IF($E$3="","",IF(INDEX('Raw Pressure Data'!$A:$ZZ,ROW()-24,MATCH($E$3,'Raw Pressure Data'!$1:$1,0))=-999,"",INDEX('Raw Pressure Data'!$A:$ZZ,ROW()-24,MATCH($E$3,'Raw Pressure Data'!$1:$1,0))+$F$3)),"") | M32: =IFERROR(IF($E$4="","",IF(INDEX('Raw Pressure Data'!$A:$ZZ,ROW()-24,MATCH($E$4,'Raw Pressure Data'!$1:$1,0))=-999,"",INDEX('Raw Pressure Data'!$A:$ZZ,ROW()-24,MATCH($E$4,'Raw Pressure Data'!$1:$1,0))+$F$4)),"") | N32: =IFERROR(IF($E$5="","",IF(INDEX('Raw Pressure Data'!$A:$ZZ,ROW()-24,MATCH($E$5,'Raw Pressure Data'!$1:$1,0))=-999,"",INDEX('Raw Pressure Data'!$A:$ZZ,ROW()-24,MATCH($E$5,'Raw Pressure Data'!$1:$1,0))+$F$5)),"") | O32: =IFERROR(IF($E$6="","",IF(INDEX('Raw Pressure Data'!$A:$ZZ,ROW()-24,MATCH($E$6,'Raw Pressure Data'!$1:$1,0))=-999,"",INDEX('Raw Pressure Data'!$A:$ZZ,ROW()-24,MATCH($E$6,'Raw Pressure Data'!$1:$1,0))+$F$6)),"") | P32: =IFERROR(IF($E$7="","",IF(INDEX('Raw Pressure Data'!$A:$ZZ,ROW()-24,MATCH($E$7,'Raw Pressure Data'!$1:$1,0))=-999,"",INDEX('Raw Pressure Data'!$A:$ZZ,ROW()-24,MATCH($E$7,'Raw Pressure Data'!$1:$1,0))+$F$7)),"") | Q32: =IFERROR(IF($E$8="","",IF(INDEX('Raw Pressure Data'!$A:$ZZ,ROW()-24,MATCH($E$8,'Raw Pressure Data'!$1:$1,0))=-999,"",INDEX('Raw Pressure Data'!$A:$ZZ,ROW()-24,MATCH($E$8,'Raw Pressure Data'!$1:$1,0))+$F$8)),"") | R32: =IFERROR(IF($E$9="","",IF(INDEX('Raw Pressure Data'!$A:$ZZ,ROW()-24,MATCH($E$9,'Raw Pressure Data'!$1:$1,0))=-999,"",INDEX('Raw Pressure Data'!$A:$ZZ,ROW()-24,MATCH($E$9,'Raw Pressure Data'!$1:$1,0))+$F$9)),"") | S32: =IFERROR(IF($E$10="","",IF(INDEX('Raw Pressure Data'!$A:$ZZ,ROW()-24,MATCH($E$10,'Raw Pressure Data'!$1:$1,0))=-999,"",INDEX('Raw Pressure Data'!$A:$ZZ,ROW()-24,MATCH($E$10,'Raw Pressure Data'!$1:$1,0))+$F$10)),"") | T32: =IFERROR(IF($E$11="","",IF(INDEX('Raw Pressure Data'!$A:$ZZ,ROW()-24,MATCH($E$11,'Raw Pressure Data'!$1:$1,0))=-999,"",INDEX('Raw Pressure Data'!$A:$ZZ,ROW()-24,MATCH($E$11,'Raw Pressure Data'!$1:$1,0))+$F$11)),"") | U32: =IFERROR(IF($E$12="","",IF(INDEX('Raw Pressure Data'!$A:$ZZ,ROW()-24,MATCH($E$12,'Raw Pressure Data'!$1:$1,0))=-999,"",INDEX('Raw Pressure Data'!$A:$ZZ,ROW()-24,MATCH($E$12,'Raw Pressure Data'!$1:$1,0))+$F$12)),"") | V32: =IFERROR(IF($E$13="","",IF(INDEX('Raw Pressure Data'!$A:$ZZ,ROW()-24,MATCH($E$13,'Raw Pressure Data'!$1:$1,0))=-999,"",INDEX('Raw Pressure Data'!$A:$ZZ,ROW()-24,MATCH($E$13,'Raw Pressure Data'!$1:$1,0))+$F$13)),"") | W32: =IFERROR(IF($E$14="","",IF(INDEX('Raw Pressure Data'!$A:$ZZ,ROW()-24,MATCH($E$14,'Raw Pressure Data'!$1:$1,0))=-999,"",INDEX('Raw Pressure Data'!$A:$ZZ,ROW()-24,MATCH($E$14,'Raw Pressure Data'!$1:$1,0))+$F$14)),"") | X32: =IFERROR(IF($E$15="","",IF(INDEX('Raw Pressure Data'!$A:$ZZ,ROW()-24,MATCH($E$15,'Raw Pressure Data'!$1:$1,0))=-999,"",INDEX('Raw Pressure Data'!$A:$ZZ,ROW()-24,MATCH($E$15,'Raw Pressure Data'!$1:$1,0))+$F$15)),"") | Y32: =IFERROR(IF($E$16="","",IF(INDEX('Raw Pressure Data'!$A:$ZZ,ROW()-24,MATCH($E$16,'Raw Pressure Data'!$1:$1,0))=-999,"",INDEX('Raw Pressure Data'!$A:$ZZ,ROW()-24,MATCH($E$16,'Raw Pressure Data'!$1:$1,0))+$F$16)),"") | Z32: =IFERROR(IF($E$17="","",IF(INDEX('Raw Pressure Data'!$A:$ZZ,ROW()-24,MATCH($E$17,'Raw Pressure Data'!$1:$1,0))=-999,"",INDEX('Raw Pressure Data'!$A:$ZZ,ROW()-24,MATCH($E$17,'Raw Pressure Data'!$1:$1,0))+$F$17)),"") | AA32: =IFERROR(IF($E$18="","",IF(INDEX('Raw Pressure Data'!$A:$ZZ,ROW()-24,MATCH($E$18,'Raw Pressure Data'!$1:$1,0))=-999,"",INDEX('Raw Pressure Data'!$A:$ZZ,ROW()-24,MATCH($E$18,'Raw Pressure Data'!$1:$1,0))+$F$18)),"") | AB32: =IFERROR(IF($E$19="","",IF(INDEX('Raw Pressure Data'!$A:$ZZ,ROW()-24,MATCH($E$19,'Raw Pressure Data'!$1:$1,0))=-999,"",INDEX('Raw Pressure Data'!$A:$ZZ,ROW()-24,MATCH($E$19,'Raw Pressure Data'!$1:$1,0))+$F$19)),"") | AC32: =IFERROR(IF($E$20="","",IF(INDEX('Raw Pressure Data'!$A:$ZZ,ROW()-24,MATCH($E$20,'Raw Pressure Data'!$1:$1,0))=-999,"",INDEX('Raw Pressure Data'!$A:$ZZ,ROW()-24,MATCH($E$20,'Raw Pressure Data'!$1:$1,0))+$F$20)),"") | AD32: =IFERROR(IF($E$21="","",IF(INDEX('Raw Pressure Data'!$A:$ZZ,ROW()-24,MATCH($E$21,'Raw Pressure Data'!$1:$1,0))=-999,"",INDEX('Raw Pressure Data'!$A:$ZZ,ROW()-24,MATCH($E$21,'Raw Pressure Data'!$1:$1,0))+$F$21)),"") | AE32: =IFERROR(IF($E$22="","",IF(INDEX('Raw Pressure Data'!$A:$ZZ,ROW()-24,MATCH($E$22,'Raw Pressure Data'!$1:$1,0))=-999,"",INDEX('Raw Pressure Data'!$A:$ZZ,ROW()-24,MATCH($E$22,'Raw Pressure Data'!$1:$1,0))+$F$22)),"")
